2019-11-05 20:48:57 ERROR (MainThread) [homeassistant.core] Error doing job: Task exception was never retrieved
Traceback (most recent call last):
  File "/usr/src/homeassistant/homeassistant/helpers/entity_platform.py", line 406, in _async_add_entity
    await entity.async_added_to_hass()
  File "/usr/src/homeassistant/homeassistant/components/met/weather.py", line 82, in async_added_to_hass
    await self._fetch_data()
  File "/usr/src/homeassistant/homeassistant/components/met/weather.py", line 146, in _fetch_data
    self._update()
  File "/usr/src/homeassistant/homeassistant/components/met/weather.py", line 153, in _update
    self.async_write_ha_state()
  File "/usr/src/homeassistant/homeassistant/helpers/entity.py", line 279, in async_write_ha_state
    self._async_write_ha_state()
  File "/usr/src/homeassistant/homeassistant/helpers/entity.py", line 307, in _async_write_ha_state
    attr.update(self.state_attributes or {})
  File "/usr/src/homeassistant/homeassistant/components/weather/__init__.py", line 168, in state_attributes
    forecast_entry[ATTR_FORECAST_TEMP],
KeyError: 'temperature'
2019-11-05 20:48:59 WARNING (SyncWorker_10) [homeassistant.components.sonos.media_player] Failed to initialize '192.168.1.179'
