2020-02-03 13:57:43 ERROR (MainThread) [coap] Exception CancelledError() can not be represented as errno, setting -1.
2020-02-03 13:57:43 ERROR (MainThread) [homeassistant.components.tradfri] Tradfri setup failed.
2020-02-03 14:00:21 ERROR (MainThread) [coap] Exception CancelledError() can not be represented as errno, setting -1.
2020-02-03 14:00:21 ERROR (MainThread) [coap] Exception CancelledError() can not be represented as errno, setting -1.
2020-02-03 14:24:05 ERROR (SyncWorker_18) [homeassistant.core] Error doing job: Task exception was never retrieved
Traceback (most recent call last):
  File "/usr/local/lib/python3.7/site-packages/aiocoap/transports/tinydtls.py", line 157, in _run
    yield from self._connecting
concurrent.futures._base.CancelledError

During handling of the above exception, another exception occurred:

Traceback (most recent call last):
  File "/usr/local/lib/python3.7/site-packages/aiocoap/transports/tinydtls.py", line 169, in _run
    self.coaptransport.new_error_callback(-1, self)
  File "/usr/local/lib/python3.7/site-packages/aiocoap/protocol.py", line 203, in _dispatch_error
    for key, (monitor, cancellable_timeout) in self._active_exchanges.items():
AttributeError: 'NoneType' object has no attribute 'items'
2020-02-03 14:24:05 ERROR (SyncWorker_18) [homeassistant.core] Error doing job: Task exception was never retrieved
Traceback (most recent call last):
  File "/usr/local/lib/python3.7/site-packages/aiocoap/transports/tinydtls.py", line 160, in _run
    message = yield from self._queue.get()
  File "/usr/local/lib/python3.7/site-packages/aiocoap/util/asyncio.py", line 40, in get
    priority, first = yield from self._inner.get()
  File "/usr/local/lib/python3.7/asyncio/queues.py", line 159, in get
    await getter
concurrent.futures._base.CancelledError

During handling of the above exception, another exception occurred:

Traceback (most recent call last):
  File "/usr/local/lib/python3.7/site-packages/aiocoap/transports/tinydtls.py", line 169, in _run
    self.coaptransport.new_error_callback(-1, self)
  File "/usr/local/lib/python3.7/site-packages/aiocoap/protocol.py", line 203, in _dispatch_error
    for key, (monitor, cancellable_timeout) in self._active_exchanges.items():
AttributeError: 'NoneType' object has no attribute 'items'
2020-02-03 14:24:05 ERROR (SyncWorker_18) [homeassistant.core] Error doing job: Task exception was never retrieved
Traceback (most recent call last):
  File "/usr/local/lib/python3.7/site-packages/aiocoap/transports/tinydtls.py", line 160, in _run
    message = yield from self._queue.get()
  File "/usr/local/lib/python3.7/site-packages/aiocoap/util/asyncio.py", line 40, in get
    priority, first = yield from self._inner.get()
  File "/usr/local/lib/python3.7/asyncio/queues.py", line 159, in get
    await getter
concurrent.futures._base.CancelledError

During handling of the above exception, another exception occurred:

Traceback (most recent call last):
  File "/usr/local/lib/python3.7/site-packages/aiocoap/transports/tinydtls.py", line 169, in _run
    self.coaptransport.new_error_callback(-1, self)
  File "/usr/local/lib/python3.7/site-packages/aiocoap/protocol.py", line 203, in _dispatch_error
    for key, (monitor, cancellable_timeout) in self._active_exchanges.items():
AttributeError: 'NoneType' object has no attribute 'items'
2020-02-04 20:57:41 WARNING (MainThread) [homeassistant.components.websocket_api.http.connection.1922519024] Disconnected: Did not receive auth message within 10 seconds
2020-02-09 22:07:15 WARNING (MainThread) [asyncio] socket.send() raised exception.
