2020-11-22 19:37:24 WARNING (MainThread) [homeassistant.components.http.ban] Login attempt or request with invalid authentication from 192.168.1.18
2020-11-22 22:30:16 ERROR (MainThread) [homeassistant.components.websocket_api.http.connection.1919805296] 3: resource, /lights/9/state, not available
Traceback (most recent call last):
  File "/usr/src/homeassistant/homeassistant/components/websocket_api/commands.py", line 130, in handle_call_service
    connection.context(msg),
  File "/usr/src/homeassistant/homeassistant/core.py", line 1234, in async_call
    await asyncio.shield(self._execute_service(handler, service_call))
  File "/usr/src/homeassistant/homeassistant/core.py", line 1259, in _execute_service
    await handler.func(service_call)
  File "/usr/src/homeassistant/homeassistant/helpers/entity_component.py", line 213, in handle_service
    self._platforms.values(), func, call, service_name, required_features
  File "/usr/src/homeassistant/homeassistant/helpers/service.py", line 349, in entity_service_call
    future.result()  # pop exception if have
  File "/usr/src/homeassistant/homeassistant/helpers/service.py", line 371, in _handle_service_platform_call
    await getattr(entity, func)(**data)
  File "/usr/src/homeassistant/homeassistant/components/hue/light.py", line 440, in async_turn_off
    await self.light.set_state(**command)
  File "/usr/local/lib/python3.7/site-packages/aiohue/lights.py", line 117, in set_state
    json=data)
  File "/usr/local/lib/python3.7/site-packages/aiohue/bridge.py", line 64, in request
    _raise_on_error(data)
  File "/usr/local/lib/python3.7/site-packages/aiohue/bridge.py", line 78, in _raise_on_error
    raise_error(data['error'])
  File "/usr/local/lib/python3.7/site-packages/aiohue/errors.py", line 39, in raise_error
    raise cls("{}: {}".format(type, error['description']))
aiohue.errors.AiohueException: 3: resource, /lights/9/state, not available
2020-11-22 22:30:19 ERROR (MainThread) [homeassistant.components.websocket_api.http.connection.1919805296] 3: resource, /lights/9/state, not available
Traceback (most recent call last):
  File "/usr/src/homeassistant/homeassistant/components/websocket_api/commands.py", line 130, in handle_call_service
    connection.context(msg),
  File "/usr/src/homeassistant/homeassistant/core.py", line 1234, in async_call
    await asyncio.shield(self._execute_service(handler, service_call))
  File "/usr/src/homeassistant/homeassistant/core.py", line 1259, in _execute_service
    await handler.func(service_call)
  File "/usr/src/homeassistant/homeassistant/components/light/__init__.py", line 310, in async_handle_light_on_service
    await light.async_turn_on(**pars)
  File "/usr/src/homeassistant/homeassistant/components/hue/light.py", line 417, in async_turn_on
    await self.light.set_state(**command)
  File "/usr/local/lib/python3.7/site-packages/aiohue/lights.py", line 117, in set_state
    json=data)
  File "/usr/local/lib/python3.7/site-packages/aiohue/bridge.py", line 64, in request
    _raise_on_error(data)
  File "/usr/local/lib/python3.7/site-packages/aiohue/bridge.py", line 78, in _raise_on_error
    raise_error(data['error'])
  File "/usr/local/lib/python3.7/site-packages/aiohue/errors.py", line 39, in raise_error
    raise cls("{}: {}".format(type, error['description']))
aiohue.errors.AiohueException: 3: resource, /lights/9/state, not available
2020-11-22 22:30:35 ERROR (MainThread) [homeassistant.components.websocket_api.http.connection.1919805296] 3: resource, /lights/9/state, not available
Traceback (most recent call last):
  File "/usr/src/homeassistant/homeassistant/components/websocket_api/commands.py", line 130, in handle_call_service
    connection.context(msg),
  File "/usr/src/homeassistant/homeassistant/core.py", line 1234, in async_call
    await asyncio.shield(self._execute_service(handler, service_call))
  File "/usr/src/homeassistant/homeassistant/core.py", line 1259, in _execute_service
    await handler.func(service_call)
  File "/usr/src/homeassistant/homeassistant/helpers/entity_component.py", line 213, in handle_service
    self._platforms.values(), func, call, service_name, required_features
  File "/usr/src/homeassistant/homeassistant/helpers/service.py", line 349, in entity_service_call
    future.result()  # pop exception if have
  File "/usr/src/homeassistant/homeassistant/helpers/service.py", line 371, in _handle_service_platform_call
    await getattr(entity, func)(**data)
  File "/usr/src/homeassistant/homeassistant/components/hue/light.py", line 440, in async_turn_off
    await self.light.set_state(**command)
  File "/usr/local/lib/python3.7/site-packages/aiohue/lights.py", line 117, in set_state
    json=data)
  File "/usr/local/lib/python3.7/site-packages/aiohue/bridge.py", line 64, in request
    _raise_on_error(data)
  File "/usr/local/lib/python3.7/site-packages/aiohue/bridge.py", line 78, in _raise_on_error
    raise_error(data['error'])
  File "/usr/local/lib/python3.7/site-packages/aiohue/errors.py", line 39, in raise_error
    raise cls("{}: {}".format(type, error['description']))
aiohue.errors.AiohueException: 3: resource, /lights/9/state, not available
2020-11-22 22:30:36 ERROR (MainThread) [homeassistant.components.websocket_api.http.connection.1919805296] 3: resource, /lights/9/state, not available
Traceback (most recent call last):
  File "/usr/src/homeassistant/homeassistant/components/websocket_api/commands.py", line 130, in handle_call_service
    connection.context(msg),
  File "/usr/src/homeassistant/homeassistant/core.py", line 1234, in async_call
    await asyncio.shield(self._execute_service(handler, service_call))
  File "/usr/src/homeassistant/homeassistant/core.py", line 1259, in _execute_service
    await handler.func(service_call)
  File "/usr/src/homeassistant/homeassistant/components/light/__init__.py", line 310, in async_handle_light_on_service
    await light.async_turn_on(**pars)
  File "/usr/src/homeassistant/homeassistant/components/hue/light.py", line 417, in async_turn_on
    await self.light.set_state(**command)
  File "/usr/local/lib/python3.7/site-packages/aiohue/lights.py", line 117, in set_state
    json=data)
  File "/usr/local/lib/python3.7/site-packages/aiohue/bridge.py", line 64, in request
    _raise_on_error(data)
  File "/usr/local/lib/python3.7/site-packages/aiohue/bridge.py", line 78, in _raise_on_error
    raise_error(data['error'])
  File "/usr/local/lib/python3.7/site-packages/aiohue/errors.py", line 39, in raise_error
    raise cls("{}: {}".format(type, error['description']))
aiohue.errors.AiohueException: 3: resource, /lights/9/state, not available
2020-11-22 22:30:36 ERROR (MainThread) [homeassistant.components.websocket_api.http.connection.1919805296] 3: resource, /lights/9/state, not available
Traceback (most recent call last):
  File "/usr/src/homeassistant/homeassistant/components/websocket_api/commands.py", line 130, in handle_call_service
    connection.context(msg),
  File "/usr/src/homeassistant/homeassistant/core.py", line 1234, in async_call
    await asyncio.shield(self._execute_service(handler, service_call))
  File "/usr/src/homeassistant/homeassistant/core.py", line 1259, in _execute_service
    await handler.func(service_call)
  File "/usr/src/homeassistant/homeassistant/helpers/entity_component.py", line 213, in handle_service
    self._platforms.values(), func, call, service_name, required_features
  File "/usr/src/homeassistant/homeassistant/helpers/service.py", line 349, in entity_service_call
    future.result()  # pop exception if have
  File "/usr/src/homeassistant/homeassistant/helpers/service.py", line 371, in _handle_service_platform_call
    await getattr(entity, func)(**data)
  File "/usr/src/homeassistant/homeassistant/components/hue/light.py", line 440, in async_turn_off
    await self.light.set_state(**command)
  File "/usr/local/lib/python3.7/site-packages/aiohue/lights.py", line 117, in set_state
    json=data)
  File "/usr/local/lib/python3.7/site-packages/aiohue/bridge.py", line 64, in request
    _raise_on_error(data)
  File "/usr/local/lib/python3.7/site-packages/aiohue/bridge.py", line 78, in _raise_on_error
    raise_error(data['error'])
  File "/usr/local/lib/python3.7/site-packages/aiohue/errors.py", line 39, in raise_error
    raise cls("{}: {}".format(type, error['description']))
aiohue.errors.AiohueException: 3: resource, /lights/9/state, not available
2020-11-22 22:30:37 ERROR (MainThread) [homeassistant.components.websocket_api.http.connection.1919805296] 3: resource, /lights/9/state, not available
Traceback (most recent call last):
  File "/usr/src/homeassistant/homeassistant/components/websocket_api/commands.py", line 130, in handle_call_service
    connection.context(msg),
  File "/usr/src/homeassistant/homeassistant/core.py", line 1234, in async_call
    await asyncio.shield(self._execute_service(handler, service_call))
  File "/usr/src/homeassistant/homeassistant/core.py", line 1259, in _execute_service
    await handler.func(service_call)
  File "/usr/src/homeassistant/homeassistant/components/light/__init__.py", line 310, in async_handle_light_on_service
    await light.async_turn_on(**pars)
  File "/usr/src/homeassistant/homeassistant/components/hue/light.py", line 417, in async_turn_on
    await self.light.set_state(**command)
  File "/usr/local/lib/python3.7/site-packages/aiohue/lights.py", line 117, in set_state
    json=data)
  File "/usr/local/lib/python3.7/site-packages/aiohue/bridge.py", line 64, in request
    _raise_on_error(data)
  File "/usr/local/lib/python3.7/site-packages/aiohue/bridge.py", line 78, in _raise_on_error
    raise_error(data['error'])
  File "/usr/local/lib/python3.7/site-packages/aiohue/errors.py", line 39, in raise_error
    raise cls("{}: {}".format(type, error['description']))
aiohue.errors.AiohueException: 3: resource, /lights/9/state, not available
2020-11-22 22:30:37 ERROR (MainThread) [homeassistant.components.websocket_api.http.connection.1919805296] 3: resource, /lights/9/state, not available
Traceback (most recent call last):
  File "/usr/src/homeassistant/homeassistant/components/websocket_api/commands.py", line 130, in handle_call_service
    connection.context(msg),
  File "/usr/src/homeassistant/homeassistant/core.py", line 1234, in async_call
    await asyncio.shield(self._execute_service(handler, service_call))
  File "/usr/src/homeassistant/homeassistant/core.py", line 1259, in _execute_service
    await handler.func(service_call)
  File "/usr/src/homeassistant/homeassistant/helpers/entity_component.py", line 213, in handle_service
    self._platforms.values(), func, call, service_name, required_features
  File "/usr/src/homeassistant/homeassistant/helpers/service.py", line 349, in entity_service_call
    future.result()  # pop exception if have
  File "/usr/src/homeassistant/homeassistant/helpers/service.py", line 371, in _handle_service_platform_call
    await getattr(entity, func)(**data)
  File "/usr/src/homeassistant/homeassistant/components/hue/light.py", line 440, in async_turn_off
    await self.light.set_state(**command)
  File "/usr/local/lib/python3.7/site-packages/aiohue/lights.py", line 117, in set_state
    json=data)
  File "/usr/local/lib/python3.7/site-packages/aiohue/bridge.py", line 64, in request
    _raise_on_error(data)
  File "/usr/local/lib/python3.7/site-packages/aiohue/bridge.py", line 78, in _raise_on_error
    raise_error(data['error'])
  File "/usr/local/lib/python3.7/site-packages/aiohue/errors.py", line 39, in raise_error
    raise cls("{}: {}".format(type, error['description']))
aiohue.errors.AiohueException: 3: resource, /lights/9/state, not available
2020-11-23 08:14:50 ERROR (MainThread) [homeassistant.core] Error doing job: Task exception was never retrieved
Traceback (most recent call last):
  File "/usr/src/homeassistant/homeassistant/core.py", line 1234, in async_call
    await asyncio.shield(self._execute_service(handler, service_call))
  File "/usr/src/homeassistant/homeassistant/core.py", line 1259, in _execute_service
    await handler.func(service_call)
  File "/usr/src/homeassistant/homeassistant/helpers/entity_component.py", line 213, in handle_service
    self._platforms.values(), func, call, service_name, required_features
  File "/usr/src/homeassistant/homeassistant/helpers/service.py", line 349, in entity_service_call
    future.result()  # pop exception if have
  File "/usr/src/homeassistant/homeassistant/helpers/service.py", line 371, in _handle_service_platform_call
    await getattr(entity, func)(**data)
  File "/usr/src/homeassistant/homeassistant/components/hue/light.py", line 440, in async_turn_off
    await self.light.set_state(**command)
  File "/usr/local/lib/python3.7/site-packages/aiohue/lights.py", line 117, in set_state
    json=data)
  File "/usr/local/lib/python3.7/site-packages/aiohue/bridge.py", line 64, in request
    _raise_on_error(data)
  File "/usr/local/lib/python3.7/site-packages/aiohue/bridge.py", line 78, in _raise_on_error
    raise_error(data['error'])
  File "/usr/local/lib/python3.7/site-packages/aiohue/errors.py", line 39, in raise_error
    raise cls("{}: {}".format(type, error['description']))
aiohue.errors.AiohueException: 3: resource, /lights/5/state, not available
2020-11-23 10:00:00 ERROR (MainThread) [homeassistant.components.automation] Error while executing automation automation.reset_good_night. Service not found for call_service at pos 1: Unable to find service state/turn_off
2020-11-23 15:40:38 ERROR (MainThread) [homeassistant.core] Error doing job: Task exception was never retrieved
Traceback (most recent call last):
  File "/usr/src/homeassistant/homeassistant/core.py", line 1234, in async_call
    await asyncio.shield(self._execute_service(handler, service_call))
  File "/usr/src/homeassistant/homeassistant/core.py", line 1259, in _execute_service
    await handler.func(service_call)
  File "/usr/src/homeassistant/homeassistant/components/light/__init__.py", line 310, in async_handle_light_on_service
    await light.async_turn_on(**pars)
  File "/usr/src/homeassistant/homeassistant/components/hue/light.py", line 417, in async_turn_on
    await self.light.set_state(**command)
  File "/usr/local/lib/python3.7/site-packages/aiohue/lights.py", line 117, in set_state
    json=data)
  File "/usr/local/lib/python3.7/site-packages/aiohue/bridge.py", line 64, in request
    _raise_on_error(data)
  File "/usr/local/lib/python3.7/site-packages/aiohue/bridge.py", line 78, in _raise_on_error
    raise_error(data['error'])
  File "/usr/local/lib/python3.7/site-packages/aiohue/errors.py", line 39, in raise_error
    raise cls("{}: {}".format(type, error['description']))
aiohue.errors.AiohueException: 3: resource, /lights/5/state, not available
2020-11-23 15:40:40 ERROR (MainThread) [homeassistant.core] Error doing job: Task exception was never retrieved
Traceback (most recent call last):
  File "/usr/src/homeassistant/homeassistant/core.py", line 1234, in async_call
    await asyncio.shield(self._execute_service(handler, service_call))
  File "/usr/src/homeassistant/homeassistant/core.py", line 1259, in _execute_service
    await handler.func(service_call)
  File "/usr/src/homeassistant/homeassistant/components/light/__init__.py", line 310, in async_handle_light_on_service
    await light.async_turn_on(**pars)
  File "/usr/src/homeassistant/homeassistant/components/hue/light.py", line 417, in async_turn_on
    await self.light.set_state(**command)
  File "/usr/local/lib/python3.7/site-packages/aiohue/lights.py", line 117, in set_state
    json=data)
  File "/usr/local/lib/python3.7/site-packages/aiohue/bridge.py", line 64, in request
    _raise_on_error(data)
  File "/usr/local/lib/python3.7/site-packages/aiohue/bridge.py", line 78, in _raise_on_error
    raise_error(data['error'])
  File "/usr/local/lib/python3.7/site-packages/aiohue/errors.py", line 39, in raise_error
    raise cls("{}: {}".format(type, error['description']))
aiohue.errors.AiohueException: 3: resource, /lights/5/state, not available
2020-11-23 15:42:21 ERROR (MainThread) [homeassistant.core] Error doing job: Task exception was never retrieved
Traceback (most recent call last):
  File "/usr/src/homeassistant/homeassistant/helpers/script.py", line 162, in async_run
    await self._handle_action(action, variables, context)
  File "/usr/src/homeassistant/homeassistant/helpers/script.py", line 246, in _handle_action
    await self._actions[_determine_action(action)](action, variables, context)
  File "/usr/src/homeassistant/homeassistant/helpers/script.py", line 329, in _async_call_service
    context=context,
  File "/usr/src/homeassistant/homeassistant/helpers/service.py", line 98, in async_call_from_config
    domain, service_name, service_data, blocking=blocking, context=context
  File "/usr/src/homeassistant/homeassistant/core.py", line 1234, in async_call
    await asyncio.shield(self._execute_service(handler, service_call))
  File "/usr/src/homeassistant/homeassistant/core.py", line 1259, in _execute_service
    await handler.func(service_call)
  File "/usr/src/homeassistant/homeassistant/components/light/__init__.py", line 310, in async_handle_light_on_service
    await light.async_turn_on(**pars)
  File "/usr/src/homeassistant/homeassistant/components/hue/light.py", line 417, in async_turn_on
    await self.light.set_state(**command)
  File "/usr/local/lib/python3.7/site-packages/aiohue/lights.py", line 117, in set_state
    json=data)
  File "/usr/local/lib/python3.7/site-packages/aiohue/bridge.py", line 64, in request
    _raise_on_error(data)
  File "/usr/local/lib/python3.7/site-packages/aiohue/bridge.py", line 78, in _raise_on_error
    raise_error(data['error'])
  File "/usr/local/lib/python3.7/site-packages/aiohue/errors.py", line 39, in raise_error
    raise cls("{}: {}".format(type, error['description']))
aiohue.errors.AiohueException: 3: resource, /lights/5/state, not available
2020-11-24 08:16:55 ERROR (MainThread) [homeassistant.core] Error doing job: Task exception was never retrieved
Traceback (most recent call last):
  File "/usr/src/homeassistant/homeassistant/core.py", line 1234, in async_call
    await asyncio.shield(self._execute_service(handler, service_call))
  File "/usr/src/homeassistant/homeassistant/core.py", line 1259, in _execute_service
    await handler.func(service_call)
  File "/usr/src/homeassistant/homeassistant/helpers/entity_component.py", line 213, in handle_service
    self._platforms.values(), func, call, service_name, required_features
  File "/usr/src/homeassistant/homeassistant/helpers/service.py", line 349, in entity_service_call
    future.result()  # pop exception if have
  File "/usr/src/homeassistant/homeassistant/helpers/service.py", line 371, in _handle_service_platform_call
    await getattr(entity, func)(**data)
  File "/usr/src/homeassistant/homeassistant/components/hue/light.py", line 440, in async_turn_off
    await self.light.set_state(**command)
  File "/usr/local/lib/python3.7/site-packages/aiohue/lights.py", line 117, in set_state
    json=data)
  File "/usr/local/lib/python3.7/site-packages/aiohue/bridge.py", line 64, in request
    _raise_on_error(data)
  File "/usr/local/lib/python3.7/site-packages/aiohue/bridge.py", line 78, in _raise_on_error
    raise_error(data['error'])
  File "/usr/local/lib/python3.7/site-packages/aiohue/errors.py", line 39, in raise_error
    raise cls("{}: {}".format(type, error['description']))
aiohue.errors.AiohueException: 3: resource, /lights/5/state, not available
2020-11-24 10:00:00 ERROR (MainThread) [homeassistant.components.automation] Error while executing automation automation.reset_good_night. Service not found for call_service at pos 1: Unable to find service state/turn_off
2020-11-24 14:37:21 ERROR (MainThread) [homeassistant.components.hue.light] Unable to reach bridge 192.168.1.37 (Error requesting data from 192.168.1.37: Cannot connect to host 192.168.1.37:80 ssl:None [Connect call failed ('192.168.1.37', 80)])
2020-11-24 15:39:08 ERROR (MainThread) [homeassistant.core] Error doing job: Task exception was never retrieved
Traceback (most recent call last):
  File "/usr/src/homeassistant/homeassistant/core.py", line 1234, in async_call
    await asyncio.shield(self._execute_service(handler, service_call))
  File "/usr/src/homeassistant/homeassistant/core.py", line 1259, in _execute_service
    await handler.func(service_call)
  File "/usr/src/homeassistant/homeassistant/components/light/__init__.py", line 310, in async_handle_light_on_service
    await light.async_turn_on(**pars)
  File "/usr/src/homeassistant/homeassistant/components/hue/light.py", line 417, in async_turn_on
    await self.light.set_state(**command)
  File "/usr/local/lib/python3.7/site-packages/aiohue/lights.py", line 117, in set_state
    json=data)
  File "/usr/local/lib/python3.7/site-packages/aiohue/bridge.py", line 64, in request
    _raise_on_error(data)
  File "/usr/local/lib/python3.7/site-packages/aiohue/bridge.py", line 78, in _raise_on_error
    raise_error(data['error'])
  File "/usr/local/lib/python3.7/site-packages/aiohue/errors.py", line 39, in raise_error
    raise cls("{}: {}".format(type, error['description']))
aiohue.errors.AiohueException: 3: resource, /lights/5/state, not available
2020-11-24 15:39:10 ERROR (MainThread) [homeassistant.core] Error doing job: Task exception was never retrieved
Traceback (most recent call last):
  File "/usr/src/homeassistant/homeassistant/core.py", line 1234, in async_call
    await asyncio.shield(self._execute_service(handler, service_call))
  File "/usr/src/homeassistant/homeassistant/core.py", line 1259, in _execute_service
    await handler.func(service_call)
  File "/usr/src/homeassistant/homeassistant/components/light/__init__.py", line 310, in async_handle_light_on_service
    await light.async_turn_on(**pars)
  File "/usr/src/homeassistant/homeassistant/components/hue/light.py", line 417, in async_turn_on
    await self.light.set_state(**command)
  File "/usr/local/lib/python3.7/site-packages/aiohue/lights.py", line 117, in set_state
    json=data)
  File "/usr/local/lib/python3.7/site-packages/aiohue/bridge.py", line 64, in request
    _raise_on_error(data)
  File "/usr/local/lib/python3.7/site-packages/aiohue/bridge.py", line 78, in _raise_on_error
    raise_error(data['error'])
  File "/usr/local/lib/python3.7/site-packages/aiohue/errors.py", line 39, in raise_error
    raise cls("{}: {}".format(type, error['description']))
aiohue.errors.AiohueException: 3: resource, /lights/5/state, not available
2020-11-24 15:40:51 ERROR (MainThread) [homeassistant.core] Error doing job: Task exception was never retrieved
Traceback (most recent call last):
  File "/usr/src/homeassistant/homeassistant/helpers/script.py", line 162, in async_run
    await self._handle_action(action, variables, context)
  File "/usr/src/homeassistant/homeassistant/helpers/script.py", line 246, in _handle_action
    await self._actions[_determine_action(action)](action, variables, context)
  File "/usr/src/homeassistant/homeassistant/helpers/script.py", line 329, in _async_call_service
    context=context,
  File "/usr/src/homeassistant/homeassistant/helpers/service.py", line 98, in async_call_from_config
    domain, service_name, service_data, blocking=blocking, context=context
  File "/usr/src/homeassistant/homeassistant/core.py", line 1234, in async_call
    await asyncio.shield(self._execute_service(handler, service_call))
  File "/usr/src/homeassistant/homeassistant/core.py", line 1259, in _execute_service
    await handler.func(service_call)
  File "/usr/src/homeassistant/homeassistant/components/light/__init__.py", line 310, in async_handle_light_on_service
    await light.async_turn_on(**pars)
  File "/usr/src/homeassistant/homeassistant/components/hue/light.py", line 417, in async_turn_on
    await self.light.set_state(**command)
  File "/usr/local/lib/python3.7/site-packages/aiohue/lights.py", line 117, in set_state
    json=data)
  File "/usr/local/lib/python3.7/site-packages/aiohue/bridge.py", line 64, in request
    _raise_on_error(data)
  File "/usr/local/lib/python3.7/site-packages/aiohue/bridge.py", line 78, in _raise_on_error
    raise_error(data['error'])
  File "/usr/local/lib/python3.7/site-packages/aiohue/errors.py", line 39, in raise_error
    raise cls("{}: {}".format(type, error['description']))
aiohue.errors.AiohueException: 3: resource, /lights/5/state, not available
2020-11-25 08:20:31 ERROR (MainThread) [coap] Exception CancelledError() can not be represented as errno, setting -1.
2020-11-25 08:20:31 WARNING (MainThread) [homeassistant.components.tradfri.sensor] Observation failed for pannrum_motion
Traceback (most recent call last):
  File "/usr/local/lib/python3.7/site-packages/pytradfri/api/aiocoap_api.py", line 95, in _get_response
    r = await pr.response
  File "/usr/local/lib/python3.7/site-packages/aiocoap/protocol.py", line 816, in _run_outer
    yield from cls._run(app_request, response, weak_observation, protocol, log, exchange_monitor_factory)
  File "/usr/local/lib/python3.7/site-packages/aiocoap/protocol.py", line 865, in _run
    blockresponse = yield from blockrequest.response
aiocoap.error.RequestTimedOut
2020-11-25 08:20:31 WARNING (MainThread) [homeassistant.components.tradfri.sensor] Observation failed for TRADFRI motion sensor 4
Traceback (most recent call last):
  File "/usr/local/lib/python3.7/site-packages/pytradfri/api/aiocoap_api.py", line 95, in _get_response
    r = await pr.response
  File "/usr/local/lib/python3.7/site-packages/aiocoap/protocol.py", line 816, in _run_outer
    yield from cls._run(app_request, response, weak_observation, protocol, log, exchange_monitor_factory)
  File "/usr/local/lib/python3.7/site-packages/aiocoap/protocol.py", line 865, in _run
    blockresponse = yield from blockrequest.response
aiocoap.error.RequestTimedOut
2020-11-25 08:20:31 WARNING (MainThread) [homeassistant.components.tradfri.sensor] Observation failed for TRADFRI motion sensor 3
Traceback (most recent call last):
  File "/usr/local/lib/python3.7/site-packages/pytradfri/api/aiocoap_api.py", line 95, in _get_response
    r = await pr.response
  File "/usr/local/lib/python3.7/site-packages/aiocoap/protocol.py", line 816, in _run_outer
    yield from cls._run(app_request, response, weak_observation, protocol, log, exchange_monitor_factory)
  File "/usr/local/lib/python3.7/site-packages/aiocoap/protocol.py", line 865, in _run
    blockresponse = yield from blockrequest.response
aiocoap.error.RequestTimedOut
2020-11-25 08:20:31 WARNING (MainThread) [homeassistant.components.tradfri.sensor] Observation failed for TRADFRI remote control
Traceback (most recent call last):
  File "/usr/local/lib/python3.7/site-packages/pytradfri/api/aiocoap_api.py", line 95, in _get_response
    r = await pr.response
  File "/usr/local/lib/python3.7/site-packages/aiocoap/protocol.py", line 816, in _run_outer
    yield from cls._run(app_request, response, weak_observation, protocol, log, exchange_monitor_factory)
  File "/usr/local/lib/python3.7/site-packages/aiocoap/protocol.py", line 865, in _run
    blockresponse = yield from blockrequest.response
aiocoap.error.RequestTimedOut
2020-11-25 08:20:31 WARNING (MainThread) [homeassistant.components.tradfri.sensor] Observation failed for kallartrapp_motion
Traceback (most recent call last):
  File "/usr/local/lib/python3.7/site-packages/pytradfri/api/aiocoap_api.py", line 95, in _get_response
    r = await pr.response
  File "/usr/local/lib/python3.7/site-packages/aiocoap/protocol.py", line 816, in _run_outer
    yield from cls._run(app_request, response, weak_observation, protocol, log, exchange_monitor_factory)
  File "/usr/local/lib/python3.7/site-packages/aiocoap/protocol.py", line 865, in _run
    blockresponse = yield from blockrequest.response
aiocoap.error.RequestTimedOut
2020-11-25 08:20:31 WARNING (MainThread) [homeassistant.components.tradfri.light] Observation failed for kokbank
Traceback (most recent call last):
  File "/usr/local/lib/python3.7/site-packages/pytradfri/api/aiocoap_api.py", line 95, in _get_response
    r = await pr.response
  File "/usr/local/lib/python3.7/site-packages/aiocoap/protocol.py", line 816, in _run_outer
    yield from cls._run(app_request, response, weak_observation, protocol, log, exchange_monitor_factory)
  File "/usr/local/lib/python3.7/site-packages/aiocoap/protocol.py", line 865, in _run
    blockresponse = yield from blockrequest.response
aiocoap.error.RequestTimedOut
2020-11-25 08:20:31 WARNING (MainThread) [homeassistant.components.tradfri.light] Observation failed for tvattstuga
Traceback (most recent call last):
  File "/usr/local/lib/python3.7/site-packages/pytradfri/api/aiocoap_api.py", line 95, in _get_response
    r = await pr.response
  File "/usr/local/lib/python3.7/site-packages/aiocoap/protocol.py", line 816, in _run_outer
    yield from cls._run(app_request, response, weak_observation, protocol, log, exchange_monitor_factory)
  File "/usr/local/lib/python3.7/site-packages/aiocoap/protocol.py", line 865, in _run
    blockresponse = yield from blockrequest.response
aiocoap.error.RequestTimedOut
2020-11-25 08:20:31 WARNING (MainThread) [homeassistant.components.tradfri.light] Observation failed for sovrum_rund
Traceback (most recent call last):
  File "/usr/local/lib/python3.7/site-packages/pytradfri/api/aiocoap_api.py", line 95, in _get_response
    r = await pr.response
  File "/usr/local/lib/python3.7/site-packages/aiocoap/protocol.py", line 816, in _run_outer
    yield from cls._run(app_request, response, weak_observation, protocol, log, exchange_monitor_factory)
  File "/usr/local/lib/python3.7/site-packages/aiocoap/protocol.py", line 865, in _run
    blockresponse = yield from blockrequest.response
aiocoap.error.RequestTimedOut
2020-11-25 08:20:31 WARNING (MainThread) [homeassistant.components.tradfri.light] Observation failed for hanna_sang
Traceback (most recent call last):
  File "/usr/local/lib/python3.7/site-packages/pytradfri/api/aiocoap_api.py", line 95, in _get_response
    r = await pr.response
  File "/usr/local/lib/python3.7/site-packages/aiocoap/protocol.py", line 816, in _run_outer
    yield from cls._run(app_request, response, weak_observation, protocol, log, exchange_monitor_factory)
  File "/usr/local/lib/python3.7/site-packages/aiocoap/protocol.py", line 865, in _run
    blockresponse = yield from blockrequest.response
aiocoap.error.RequestTimedOut
2020-11-25 08:20:31 WARNING (MainThread) [homeassistant.components.tradfri.light] Observation failed for groventre_ute
Traceback (most recent call last):
  File "/usr/local/lib/python3.7/site-packages/pytradfri/api/aiocoap_api.py", line 95, in _get_response
    r = await pr.response
  File "/usr/local/lib/python3.7/site-packages/aiocoap/protocol.py", line 816, in _run_outer
    yield from cls._run(app_request, response, weak_observation, protocol, log, exchange_monitor_factory)
  File "/usr/local/lib/python3.7/site-packages/aiocoap/protocol.py", line 865, in _run
    blockresponse = yield from blockrequest.response
aiocoap.error.RequestTimedOut
2020-11-25 08:20:31 WARNING (MainThread) [homeassistant.components.tradfri.light] Observation failed for TRADFRI bulb 13
Traceback (most recent call last):
  File "/usr/local/lib/python3.7/site-packages/pytradfri/api/aiocoap_api.py", line 95, in _get_response
    r = await pr.response
  File "/usr/local/lib/python3.7/site-packages/aiocoap/protocol.py", line 816, in _run_outer
    yield from cls._run(app_request, response, weak_observation, protocol, log, exchange_monitor_factory)
  File "/usr/local/lib/python3.7/site-packages/aiocoap/protocol.py", line 865, in _run
    blockresponse = yield from blockrequest.response
aiocoap.error.RequestTimedOut
2020-11-25 08:20:31 WARNING (MainThread) [homeassistant.components.tradfri.light] Observation failed for pannrum
Traceback (most recent call last):
  File "/usr/local/lib/python3.7/site-packages/pytradfri/api/aiocoap_api.py", line 95, in _get_response
    r = await pr.response
  File "/usr/local/lib/python3.7/site-packages/aiocoap/protocol.py", line 816, in _run_outer
    yield from cls._run(app_request, response, weak_observation, protocol, log, exchange_monitor_factory)
  File "/usr/local/lib/python3.7/site-packages/aiocoap/protocol.py", line 865, in _run
    blockresponse = yield from blockrequest.response
aiocoap.error.RequestTimedOut
2020-11-25 08:20:31 WARNING (MainThread) [homeassistant.components.tradfri.light] Observation failed for tv_golvlampa
Traceback (most recent call last):
  File "/usr/local/lib/python3.7/site-packages/pytradfri/api/aiocoap_api.py", line 95, in _get_response
    r = await pr.response
  File "/usr/local/lib/python3.7/site-packages/aiocoap/protocol.py", line 816, in _run_outer
    yield from cls._run(app_request, response, weak_observation, protocol, log, exchange_monitor_factory)
  File "/usr/local/lib/python3.7/site-packages/aiocoap/protocol.py", line 865, in _run
    blockresponse = yield from blockrequest.response
aiocoap.error.RequestTimedOut
2020-11-25 08:20:31 WARNING (MainThread) [homeassistant.components.tradfri.light] Observation failed for guest_window
Traceback (most recent call last):
  File "/usr/local/lib/python3.7/site-packages/pytradfri/api/aiocoap_api.py", line 95, in _get_response
    r = await pr.response
  File "/usr/local/lib/python3.7/site-packages/aiocoap/protocol.py", line 816, in _run_outer
    yield from cls._run(app_request, response, weak_observation, protocol, log, exchange_monitor_factory)
  File "/usr/local/lib/python3.7/site-packages/aiocoap/protocol.py", line 865, in _run
    blockresponse = yield from blockrequest.response
aiocoap.error.RequestTimedOut
2020-11-25 08:20:31 WARNING (MainThread) [homeassistant.components.tradfri.light] Observation failed for TRADFRI bulb 16
Traceback (most recent call last):
  File "/usr/local/lib/python3.7/site-packages/pytradfri/api/aiocoap_api.py", line 95, in _get_response
    r = await pr.response
  File "/usr/local/lib/python3.7/site-packages/aiocoap/protocol.py", line 816, in _run_outer
    yield from cls._run(app_request, response, weak_observation, protocol, log, exchange_monitor_factory)
  File "/usr/local/lib/python3.7/site-packages/aiocoap/protocol.py", line 865, in _run
    blockresponse = yield from blockrequest.response
aiocoap.error.RequestTimedOut
2020-11-25 08:20:31 WARNING (MainThread) [homeassistant.components.tradfri.light] Observation failed for sovrum_hal
Traceback (most recent call last):
  File "/usr/local/lib/python3.7/site-packages/pytradfri/api/aiocoap_api.py", line 95, in _get_response
    r = await pr.response
  File "/usr/local/lib/python3.7/site-packages/aiocoap/protocol.py", line 816, in _run_outer
    yield from cls._run(app_request, response, weak_observation, protocol, log, exchange_monitor_factory)
  File "/usr/local/lib/python3.7/site-packages/aiocoap/protocol.py", line 865, in _run
    blockresponse = yield from blockrequest.response
aiocoap.error.RequestTimedOut
2020-11-25 08:20:31 WARNING (MainThread) [homeassistant.components.tradfri.light] Observation failed for tv_fonster
Traceback (most recent call last):
  File "/usr/local/lib/python3.7/site-packages/pytradfri/api/aiocoap_api.py", line 95, in _get_response
    r = await pr.response
  File "/usr/local/lib/python3.7/site-packages/aiocoap/protocol.py", line 816, in _run_outer
    yield from cls._run(app_request, response, weak_observation, protocol, log, exchange_monitor_factory)
  File "/usr/local/lib/python3.7/site-packages/aiocoap/protocol.py", line 865, in _run
    blockresponse = yield from blockrequest.response
aiocoap.error.RequestTimedOut
2020-11-25 08:20:31 WARNING (MainThread) [homeassistant.components.tradfri.light] Observation failed for sovrum_tak
Traceback (most recent call last):
  File "/usr/local/lib/python3.7/site-packages/pytradfri/api/aiocoap_api.py", line 95, in _get_response
    r = await pr.response
  File "/usr/local/lib/python3.7/site-packages/aiocoap/protocol.py", line 816, in _run_outer
    yield from cls._run(app_request, response, weak_observation, protocol, log, exchange_monitor_factory)
  File "/usr/local/lib/python3.7/site-packages/aiocoap/protocol.py", line 865, in _run
    blockresponse = yield from blockrequest.response
aiocoap.error.RequestTimedOut
2020-11-25 08:20:31 ERROR (MainThread) [homeassistant.core] Error doing job: Task exception was never retrieved
Traceback (most recent call last):
  File "/usr/src/homeassistant/homeassistant/core.py", line 1259, in _execute_service
    await handler.func(service_call)
  File "/usr/src/homeassistant/homeassistant/helpers/entity_component.py", line 213, in handle_service
    self._platforms.values(), func, call, service_name, required_features
  File "/usr/src/homeassistant/homeassistant/helpers/service.py", line 349, in entity_service_call
    future.result()  # pop exception if have
  File "/usr/src/homeassistant/homeassistant/helpers/service.py", line 371, in _handle_service_platform_call
    await getattr(entity, func)(**data)
  File "/usr/src/homeassistant/homeassistant/components/hue/light.py", line 440, in async_turn_off
    await self.light.set_state(**command)
  File "/usr/local/lib/python3.7/site-packages/aiohue/lights.py", line 117, in set_state
    json=data)
  File "/usr/local/lib/python3.7/site-packages/aiohue/bridge.py", line 64, in request
    _raise_on_error(data)
  File "/usr/local/lib/python3.7/site-packages/aiohue/bridge.py", line 78, in _raise_on_error
    raise_error(data['error'])
  File "/usr/local/lib/python3.7/site-packages/aiohue/errors.py", line 39, in raise_error
    raise cls("{}: {}".format(type, error['description']))
aiohue.errors.AiohueException: 3: resource, /lights/5/state, not available
2020-11-25 10:00:00 ERROR (MainThread) [homeassistant.components.automation] Error while executing automation automation.reset_good_night. Service not found for call_service at pos 1: Unable to find service state/turn_off
2020-11-25 11:15:51 ERROR (MainThread) [homeassistant.core] Error doing job: Task exception was never retrieved
Traceback (most recent call last):
  File "/usr/local/lib/python3.7/site-packages/aiocoap/transports/tinydtls.py", line 160, in _run
    message = yield from self._queue.get()
  File "/usr/local/lib/python3.7/site-packages/aiocoap/util/asyncio.py", line 40, in get
    priority, first = yield from self._inner.get()
  File "/usr/local/lib/python3.7/asyncio/queues.py", line 159, in get
    await getter
concurrent.futures._base.CancelledError

During handling of the above exception, another exception occurred:

Traceback (most recent call last):
  File "/usr/local/lib/python3.7/site-packages/aiocoap/transports/tinydtls.py", line 169, in _run
    self.coaptransport.new_error_callback(-1, self)
  File "/usr/local/lib/python3.7/site-packages/aiocoap/protocol.py", line 203, in _dispatch_error
    for key, (monitor, cancellable_timeout) in self._active_exchanges.items():
AttributeError: 'NoneType' object has no attribute 'items'
2020-11-25 11:15:51 WARNING (MainThread) [root] Observation deleted without explicit cancellation
2020-11-25 11:15:51 WARNING (MainThread) [root] Observation deleted without explicit cancellation
2020-11-25 11:15:51 WARNING (MainThread) [root] Observation deleted without explicit cancellation
2020-11-25 11:15:51 WARNING (MainThread) [root] Observation deleted without explicit cancellation
2020-11-25 11:15:51 WARNING (MainThread) [root] Observation deleted without explicit cancellation
2020-11-25 11:15:51 WARNING (MainThread) [root] Observation deleted without explicit cancellation
2020-11-25 11:15:51 WARNING (MainThread) [root] Observation deleted without explicit cancellation
2020-11-25 11:15:51 WARNING (MainThread) [root] Observation deleted without explicit cancellation
2020-11-25 11:15:51 WARNING (MainThread) [root] Observation deleted without explicit cancellation
2020-11-25 11:15:51 WARNING (MainThread) [root] Observation deleted without explicit cancellation
2020-11-25 11:15:51 WARNING (MainThread) [root] Observation deleted without explicit cancellation
2020-11-25 11:15:51 WARNING (MainThread) [root] Observation deleted without explicit cancellation
2020-11-25 11:15:51 WARNING (MainThread) [root] Observation deleted without explicit cancellation
2020-11-25 11:15:51 WARNING (MainThread) [root] Observation deleted without explicit cancellation
2020-11-25 11:15:51 WARNING (MainThread) [root] Observation deleted without explicit cancellation
2020-11-25 11:15:51 WARNING (MainThread) [root] Observation deleted without explicit cancellation
2020-11-25 11:15:51 WARNING (MainThread) [root] Observation deleted without explicit cancellation
2020-11-25 11:15:51 WARNING (MainThread) [root] Observation deleted without explicit cancellation
2020-11-25 11:15:51 ERROR (MainThread) [homeassistant.core] Error doing job: Task exception was never retrieved
Traceback (most recent call last):
  File "/usr/local/lib/python3.7/site-packages/pytradfri/api/aiocoap_api.py", line 95, in _get_response
    r = await pr.response
  File "/usr/local/lib/python3.7/site-packages/aiocoap/protocol.py", line 816, in _run_outer
    yield from cls._run(app_request, response, weak_observation, protocol, log, exchange_monitor_factory)
  File "/usr/local/lib/python3.7/site-packages/aiocoap/protocol.py", line 865, in _run
    blockresponse = yield from blockrequest.response
aiocoap.error.RequestTimedOut

During handling of the above exception, another exception occurred:

Traceback (most recent call last):
  File "/usr/src/homeassistant/homeassistant/helpers/service.py", line 371, in _handle_service_platform_call
    await getattr(entity, func)(**data)
  File "/usr/src/homeassistant/homeassistant/components/tradfri/light.py", line 256, in async_turn_off
    await self._api(self._light_control.set_state(False))
  File "/usr/local/lib/python3.7/site-packages/pytradfri/api/aiocoap_api.py", line 155, in request
    result = await self._execute(api_commands)
  File "/usr/local/lib/python3.7/site-packages/pytradfri/api/aiocoap_api.py", line 146, in _execute
    _, res = await self._get_response(msg)
  File "/usr/local/lib/python3.7/site-packages/pytradfri/api/aiocoap_api.py", line 101, in _get_response
    raise RequestTimeout('Request timed out.', e)
pytradfri.error.RequestTimeout: ('Request timed out.', RequestTimedOut())
