2020-02-14 15:58:55 WARNING (SyncWorker_3) [homeassistant.components.sonos.media_player] Failed to initialize '192.168.1.25'
2020-02-14 15:58:58 WARNING (SyncWorker_3) [homeassistant.components.sonos.media_player] Failed to initialize '192.168.1.36'
2020-02-15 07:41:04 WARNING (MainThread) [homeassistant.helpers.entity] Update of media_player.philips_tv is taking over 10 seconds
2020-02-16 10:52:33 WARNING (MainThread) [homeassistant.components.http.ban] Login attempt or request with invalid authentication from 192.168.1.59
2020-02-19 17:56:10 WARNING (MainThread) [homeassistant.helpers.entity] Update of media_player.philips_tv is taking over 10 seconds
2020-02-22 18:00:59 WARNING (MainThread) [homeassistant.helpers.entity] Update of media_player.philips_tv is taking over 10 seconds
2020-02-22 18:04:47 ERROR (MainThread) [homeassistant.components.hue.sensor_base] Unable to reach bridge 192.168.1.147 ()
2020-02-22 18:16:29 WARNING (MainThread) [homeassistant.helpers.entity] Update of media_player.philips_tv is taking over 10 seconds
2020-02-22 18:17:31 WARNING (MainThread) [homeassistant.helpers.entity] Update of media_player.philips_tv is taking over 10 seconds
2020-02-22 18:49:33 WARNING (MainThread) [homeassistant.helpers.entity] Update of media_player.philips_tv is taking over 10 seconds
2020-02-22 23:19:26 ERROR (MainThread) [coap] Exception CancelledError() can not be represented as errno, setting -1.
2020-02-22 23:19:26 ERROR (MainThread) [homeassistant.core] Error doing job: Task exception was never retrieved
Traceback (most recent call last):
  File "/usr/local/lib/python3.7/site-packages/pytradfri/api/aiocoap_api.py", line 95, in _get_response
    r = await pr.response
  File "/usr/local/lib/python3.7/site-packages/aiocoap/protocol.py", line 816, in _run_outer
    yield from cls._run(app_request, response, weak_observation, protocol, log, exchange_monitor_factory)
  File "/usr/local/lib/python3.7/site-packages/aiocoap/protocol.py", line 865, in _run
    blockresponse = yield from blockrequest.response
OSError: [Errno -1] No error information

During handling of the above exception, another exception occurred:

Traceback (most recent call last):
  File "/usr/src/homeassistant/homeassistant/core.py", line 1259, in _execute_service
    await handler.func(service_call)
  File "/usr/src/homeassistant/homeassistant/components/light/__init__.py", line 310, in async_handle_light_on_service
    await light.async_turn_on(**pars)
  File "/usr/src/homeassistant/homeassistant/components/tradfri/light.py", line 337, in async_turn_on
    await self._api(command)
  File "/usr/local/lib/python3.7/site-packages/pytradfri/api/aiocoap_api.py", line 155, in request
    result = await self._execute(api_commands)
  File "/usr/local/lib/python3.7/site-packages/pytradfri/api/aiocoap_api.py", line 146, in _execute
    _, res = await self._get_response(msg)
  File "/usr/local/lib/python3.7/site-packages/pytradfri/api/aiocoap_api.py", line 105, in _get_response
    await self._reset_protocol(e)
  File "/usr/local/lib/python3.7/site-packages/pytradfri/api/aiocoap_api.py", line 78, in _reset_protocol
    await protocol.shutdown()
  File "/usr/local/lib/python3.7/site-packages/aiocoap/protocol.py", line 133, in shutdown
    for exchange_monitor, cancellable in self._active_exchanges.values():
AttributeError: 'NoneType' object has no attribute 'values'
2020-02-22 23:19:26 ERROR (MainThread) [homeassistant.core] Error doing job: Task exception was never retrieved
Traceback (most recent call last):
  File "/usr/local/lib/python3.7/site-packages/pytradfri/api/aiocoap_api.py", line 95, in _get_response
    r = await pr.response
  File "/usr/local/lib/python3.7/site-packages/aiocoap/protocol.py", line 816, in _run_outer
    yield from cls._run(app_request, response, weak_observation, protocol, log, exchange_monitor_factory)
  File "/usr/local/lib/python3.7/site-packages/aiocoap/protocol.py", line 865, in _run
    blockresponse = yield from blockrequest.response
OSError: [Errno -1] No error information

During handling of the above exception, another exception occurred:

Traceback (most recent call last):
  File "/usr/src/homeassistant/homeassistant/core.py", line 1259, in _execute_service
    await handler.func(service_call)
  File "/usr/src/homeassistant/homeassistant/components/light/__init__.py", line 310, in async_handle_light_on_service
    await light.async_turn_on(**pars)
  File "/usr/src/homeassistant/homeassistant/components/tradfri/light.py", line 337, in async_turn_on
    await self._api(command)
  File "/usr/local/lib/python3.7/site-packages/pytradfri/api/aiocoap_api.py", line 155, in request
    result = await self._execute(api_commands)
  File "/usr/local/lib/python3.7/site-packages/pytradfri/api/aiocoap_api.py", line 146, in _execute
    _, res = await self._get_response(msg)
  File "/usr/local/lib/python3.7/site-packages/pytradfri/api/aiocoap_api.py", line 105, in _get_response
    await self._reset_protocol(e)
  File "/usr/local/lib/python3.7/site-packages/pytradfri/api/aiocoap_api.py", line 78, in _reset_protocol
    await protocol.shutdown()
  File "/usr/local/lib/python3.7/site-packages/aiocoap/protocol.py", line 133, in shutdown
    for exchange_monitor, cancellable in self._active_exchanges.values():
AttributeError: 'NoneType' object has no attribute 'values'
2020-02-22 23:19:26 ERROR (MainThread) [homeassistant.core] Error doing job: Task exception was never retrieved
Traceback (most recent call last):
  File "/usr/local/lib/python3.7/site-packages/pytradfri/api/aiocoap_api.py", line 95, in _get_response
    r = await pr.response
  File "/usr/local/lib/python3.7/site-packages/aiocoap/protocol.py", line 816, in _run_outer
    yield from cls._run(app_request, response, weak_observation, protocol, log, exchange_monitor_factory)
  File "/usr/local/lib/python3.7/site-packages/aiocoap/protocol.py", line 865, in _run
    blockresponse = yield from blockrequest.response
OSError: [Errno -1] No error information

During handling of the above exception, another exception occurred:

Traceback (most recent call last):
  File "/usr/src/homeassistant/homeassistant/core.py", line 1259, in _execute_service
    await handler.func(service_call)
  File "/usr/src/homeassistant/homeassistant/components/light/__init__.py", line 310, in async_handle_light_on_service
    await light.async_turn_on(**pars)
  File "/usr/src/homeassistant/homeassistant/components/tradfri/light.py", line 337, in async_turn_on
    await self._api(command)
  File "/usr/local/lib/python3.7/site-packages/pytradfri/api/aiocoap_api.py", line 155, in request
    result = await self._execute(api_commands)
  File "/usr/local/lib/python3.7/site-packages/pytradfri/api/aiocoap_api.py", line 146, in _execute
    _, res = await self._get_response(msg)
  File "/usr/local/lib/python3.7/site-packages/pytradfri/api/aiocoap_api.py", line 105, in _get_response
    await self._reset_protocol(e)
  File "/usr/local/lib/python3.7/site-packages/pytradfri/api/aiocoap_api.py", line 78, in _reset_protocol
    await protocol.shutdown()
  File "/usr/local/lib/python3.7/site-packages/aiocoap/protocol.py", line 133, in shutdown
    for exchange_monitor, cancellable in self._active_exchanges.values():
AttributeError: 'NoneType' object has no attribute 'values'
2020-02-22 23:19:26 ERROR (MainThread) [homeassistant.core] Error doing job: Task exception was never retrieved
Traceback (most recent call last):
  File "/usr/local/lib/python3.7/site-packages/pytradfri/api/aiocoap_api.py", line 95, in _get_response
    r = await pr.response
  File "/usr/local/lib/python3.7/site-packages/aiocoap/protocol.py", line 816, in _run_outer
    yield from cls._run(app_request, response, weak_observation, protocol, log, exchange_monitor_factory)
  File "/usr/local/lib/python3.7/site-packages/aiocoap/protocol.py", line 865, in _run
    blockresponse = yield from blockrequest.response
OSError: [Errno -1] No error information

During handling of the above exception, another exception occurred:

Traceback (most recent call last):
  File "/usr/src/homeassistant/homeassistant/core.py", line 1259, in _execute_service
    await handler.func(service_call)
  File "/usr/src/homeassistant/homeassistant/components/light/__init__.py", line 310, in async_handle_light_on_service
    await light.async_turn_on(**pars)
  File "/usr/src/homeassistant/homeassistant/components/tradfri/light.py", line 337, in async_turn_on
    await self._api(command)
  File "/usr/local/lib/python3.7/site-packages/pytradfri/api/aiocoap_api.py", line 155, in request
    result = await self._execute(api_commands)
  File "/usr/local/lib/python3.7/site-packages/pytradfri/api/aiocoap_api.py", line 146, in _execute
    _, res = await self._get_response(msg)
  File "/usr/local/lib/python3.7/site-packages/pytradfri/api/aiocoap_api.py", line 105, in _get_response
    await self._reset_protocol(e)
  File "/usr/local/lib/python3.7/site-packages/pytradfri/api/aiocoap_api.py", line 78, in _reset_protocol
    await protocol.shutdown()
  File "/usr/local/lib/python3.7/site-packages/aiocoap/protocol.py", line 133, in shutdown
    for exchange_monitor, cancellable in self._active_exchanges.values():
AttributeError: 'NoneType' object has no attribute 'values'
2020-02-22 23:19:26 WARNING (MainThread) [homeassistant.components.tradfri.sensor] Observation failed for pannrum_motion
Traceback (most recent call last):
  File "/usr/local/lib/python3.7/site-packages/pytradfri/api/aiocoap_api.py", line 95, in _get_response
    r = await pr.response
  File "/usr/local/lib/python3.7/site-packages/aiocoap/protocol.py", line 816, in _run_outer
    yield from cls._run(app_request, response, weak_observation, protocol, log, exchange_monitor_factory)
  File "/usr/local/lib/python3.7/site-packages/aiocoap/protocol.py", line 865, in _run
    blockresponse = yield from blockrequest.response
aiocoap.error.RequestTimedOut
2020-02-22 23:19:26 WARNING (MainThread) [homeassistant.components.tradfri.sensor] Observation failed for TRADFRI remote control
Traceback (most recent call last):
  File "/usr/local/lib/python3.7/site-packages/pytradfri/api/aiocoap_api.py", line 95, in _get_response
    r = await pr.response
  File "/usr/local/lib/python3.7/site-packages/aiocoap/protocol.py", line 816, in _run_outer
    yield from cls._run(app_request, response, weak_observation, protocol, log, exchange_monitor_factory)
  File "/usr/local/lib/python3.7/site-packages/aiocoap/protocol.py", line 865, in _run
    blockresponse = yield from blockrequest.response
aiocoap.error.RequestTimedOut
2020-02-22 23:19:26 WARNING (MainThread) [homeassistant.components.tradfri.sensor] Observation failed for kallartrapp_motion
Traceback (most recent call last):
  File "/usr/local/lib/python3.7/site-packages/pytradfri/api/aiocoap_api.py", line 95, in _get_response
    r = await pr.response
  File "/usr/local/lib/python3.7/site-packages/aiocoap/protocol.py", line 816, in _run_outer
    yield from cls._run(app_request, response, weak_observation, protocol, log, exchange_monitor_factory)
  File "/usr/local/lib/python3.7/site-packages/aiocoap/protocol.py", line 865, in _run
    blockresponse = yield from blockrequest.response
aiocoap.error.RequestTimedOut
2020-02-22 23:19:26 WARNING (MainThread) [homeassistant.components.tradfri.sensor] Observation failed for TRADFRI motion sensor 3
Traceback (most recent call last):
  File "/usr/local/lib/python3.7/site-packages/pytradfri/api/aiocoap_api.py", line 95, in _get_response
    r = await pr.response
  File "/usr/local/lib/python3.7/site-packages/aiocoap/protocol.py", line 816, in _run_outer
    yield from cls._run(app_request, response, weak_observation, protocol, log, exchange_monitor_factory)
  File "/usr/local/lib/python3.7/site-packages/aiocoap/protocol.py", line 865, in _run
    blockresponse = yield from blockrequest.response
aiocoap.error.RequestTimedOut
2020-02-22 23:19:26 WARNING (MainThread) [homeassistant.components.tradfri.light] Observation failed for svartvitt
Traceback (most recent call last):
  File "/usr/local/lib/python3.7/site-packages/pytradfri/api/aiocoap_api.py", line 95, in _get_response
    r = await pr.response
  File "/usr/local/lib/python3.7/site-packages/aiocoap/protocol.py", line 816, in _run_outer
    yield from cls._run(app_request, response, weak_observation, protocol, log, exchange_monitor_factory)
  File "/usr/local/lib/python3.7/site-packages/aiocoap/protocol.py", line 865, in _run
    blockresponse = yield from blockrequest.response
aiocoap.error.RequestTimedOut
2020-02-22 23:19:26 WARNING (MainThread) [homeassistant.components.tradfri.light] Observation failed for pannrum
Traceback (most recent call last):
  File "/usr/local/lib/python3.7/site-packages/pytradfri/api/aiocoap_api.py", line 95, in _get_response
    r = await pr.response
  File "/usr/local/lib/python3.7/site-packages/aiocoap/protocol.py", line 816, in _run_outer
    yield from cls._run(app_request, response, weak_observation, protocol, log, exchange_monitor_factory)
  File "/usr/local/lib/python3.7/site-packages/aiocoap/protocol.py", line 865, in _run
    blockresponse = yield from blockrequest.response
aiocoap.error.RequestTimedOut
2020-02-22 23:19:26 WARNING (MainThread) [homeassistant.components.tradfri.light] Observation failed for kokbank
Traceback (most recent call last):
  File "/usr/local/lib/python3.7/site-packages/pytradfri/api/aiocoap_api.py", line 95, in _get_response
    r = await pr.response
  File "/usr/local/lib/python3.7/site-packages/aiocoap/protocol.py", line 816, in _run_outer
    yield from cls._run(app_request, response, weak_observation, protocol, log, exchange_monitor_factory)
  File "/usr/local/lib/python3.7/site-packages/aiocoap/protocol.py", line 865, in _run
    blockresponse = yield from blockrequest.response
aiocoap.error.RequestTimedOut
2020-02-22 23:19:26 WARNING (MainThread) [homeassistant.components.tradfri.light] Observation failed for groventre
Traceback (most recent call last):
  File "/usr/local/lib/python3.7/site-packages/pytradfri/api/aiocoap_api.py", line 95, in _get_response
    r = await pr.response
  File "/usr/local/lib/python3.7/site-packages/aiocoap/protocol.py", line 816, in _run_outer
    yield from cls._run(app_request, response, weak_observation, protocol, log, exchange_monitor_factory)
  File "/usr/local/lib/python3.7/site-packages/aiocoap/protocol.py", line 865, in _run
    blockresponse = yield from blockrequest.response
aiocoap.error.RequestTimedOut
2020-02-22 23:19:26 WARNING (MainThread) [homeassistant.components.tradfri.light] Observation failed for kallartrapp
Traceback (most recent call last):
  File "/usr/local/lib/python3.7/site-packages/pytradfri/api/aiocoap_api.py", line 95, in _get_response
    r = await pr.response
  File "/usr/local/lib/python3.7/site-packages/aiocoap/protocol.py", line 816, in _run_outer
    yield from cls._run(app_request, response, weak_observation, protocol, log, exchange_monitor_factory)
  File "/usr/local/lib/python3.7/site-packages/aiocoap/protocol.py", line 865, in _run
    blockresponse = yield from blockrequest.response
aiocoap.error.RequestTimedOut
2020-02-22 23:19:26 WARNING (MainThread) [homeassistant.components.tradfri.light] Observation failed for nattduk_adam
Traceback (most recent call last):
  File "/usr/local/lib/python3.7/site-packages/pytradfri/api/aiocoap_api.py", line 95, in _get_response
    r = await pr.response
  File "/usr/local/lib/python3.7/site-packages/aiocoap/protocol.py", line 816, in _run_outer
    yield from cls._run(app_request, response, weak_observation, protocol, log, exchange_monitor_factory)
  File "/usr/local/lib/python3.7/site-packages/aiocoap/protocol.py", line 865, in _run
    blockresponse = yield from blockrequest.response
aiocoap.error.RequestTimedOut
2020-02-22 23:19:26 WARNING (MainThread) [homeassistant.components.tradfri.light] Observation failed for tvattstuga
Traceback (most recent call last):
  File "/usr/local/lib/python3.7/site-packages/pytradfri/api/aiocoap_api.py", line 95, in _get_response
    r = await pr.response
  File "/usr/local/lib/python3.7/site-packages/aiocoap/protocol.py", line 816, in _run_outer
    yield from cls._run(app_request, response, weak_observation, protocol, log, exchange_monitor_factory)
  File "/usr/local/lib/python3.7/site-packages/aiocoap/protocol.py", line 865, in _run
    blockresponse = yield from blockrequest.response
aiocoap.error.RequestTimedOut
2020-02-22 23:19:26 WARNING (MainThread) [homeassistant.components.tradfri.light] Observation failed for svartvitt_2
Traceback (most recent call last):
  File "/usr/local/lib/python3.7/site-packages/pytradfri/api/aiocoap_api.py", line 95, in _get_response
    r = await pr.response
  File "/usr/local/lib/python3.7/site-packages/aiocoap/protocol.py", line 816, in _run_outer
    yield from cls._run(app_request, response, weak_observation, protocol, log, exchange_monitor_factory)
  File "/usr/local/lib/python3.7/site-packages/aiocoap/protocol.py", line 865, in _run
    blockresponse = yield from blockrequest.response
aiocoap.error.RequestTimedOut
2020-02-22 23:19:26 WARNING (MainThread) [homeassistant.components.tradfri.light] Observation failed for sovrum_hal
Traceback (most recent call last):
  File "/usr/local/lib/python3.7/site-packages/pytradfri/api/aiocoap_api.py", line 95, in _get_response
    r = await pr.response
  File "/usr/local/lib/python3.7/site-packages/aiocoap/protocol.py", line 816, in _run_outer
    yield from cls._run(app_request, response, weak_observation, protocol, log, exchange_monitor_factory)
  File "/usr/local/lib/python3.7/site-packages/aiocoap/protocol.py", line 865, in _run
    blockresponse = yield from blockrequest.response
aiocoap.error.RequestTimedOut
2020-02-22 23:19:26 WARNING (MainThread) [homeassistant.components.tradfri.light] Observation failed for lill_hall
Traceback (most recent call last):
  File "/usr/local/lib/python3.7/site-packages/pytradfri/api/aiocoap_api.py", line 95, in _get_response
    r = await pr.response
  File "/usr/local/lib/python3.7/site-packages/aiocoap/protocol.py", line 816, in _run_outer
    yield from cls._run(app_request, response, weak_observation, protocol, log, exchange_monitor_factory)
  File "/usr/local/lib/python3.7/site-packages/aiocoap/protocol.py", line 865, in _run
    blockresponse = yield from blockrequest.response
aiocoap.error.RequestTimedOut
2020-02-22 23:19:26 WARNING (MainThread) [homeassistant.components.tradfri.light] Observation failed for piano
Traceback (most recent call last):
  File "/usr/local/lib/python3.7/site-packages/pytradfri/api/aiocoap_api.py", line 95, in _get_response
    r = await pr.response
  File "/usr/local/lib/python3.7/site-packages/aiocoap/protocol.py", line 816, in _run_outer
    yield from cls._run(app_request, response, weak_observation, protocol, log, exchange_monitor_factory)
  File "/usr/local/lib/python3.7/site-packages/aiocoap/protocol.py", line 865, in _run
    blockresponse = yield from blockrequest.response
aiocoap.error.RequestTimedOut
2020-02-22 23:19:26 WARNING (MainThread) [homeassistant.components.tradfri.light] Observation failed for kallarhall
Traceback (most recent call last):
  File "/usr/local/lib/python3.7/site-packages/pytradfri/api/aiocoap_api.py", line 95, in _get_response
    r = await pr.response
  File "/usr/local/lib/python3.7/site-packages/aiocoap/protocol.py", line 816, in _run_outer
    yield from cls._run(app_request, response, weak_observation, protocol, log, exchange_monitor_factory)
  File "/usr/local/lib/python3.7/site-packages/aiocoap/protocol.py", line 865, in _run
    blockresponse = yield from blockrequest.response
aiocoap.error.RequestTimedOut
2020-02-22 23:19:26 WARNING (MainThread) [homeassistant.components.tradfri.light] Observation failed for sovrum_tak
Traceback (most recent call last):
  File "/usr/local/lib/python3.7/site-packages/pytradfri/api/aiocoap_api.py", line 95, in _get_response
    r = await pr.response
  File "/usr/local/lib/python3.7/site-packages/aiocoap/protocol.py", line 816, in _run_outer
    yield from cls._run(app_request, response, weak_observation, protocol, log, exchange_monitor_factory)
  File "/usr/local/lib/python3.7/site-packages/aiocoap/protocol.py", line 865, in _run
    blockresponse = yield from blockrequest.response
aiocoap.error.RequestTimedOut
2020-02-22 23:19:26 ERROR (MainThread) [homeassistant.core] Error doing job: Task exception was never retrieved
Traceback (most recent call last):
  File "/usr/local/lib/python3.7/site-packages/pytradfri/api/aiocoap_api.py", line 95, in _get_response
    r = await pr.response
  File "/usr/local/lib/python3.7/site-packages/aiocoap/protocol.py", line 816, in _run_outer
    yield from cls._run(app_request, response, weak_observation, protocol, log, exchange_monitor_factory)
  File "/usr/local/lib/python3.7/site-packages/aiocoap/protocol.py", line 865, in _run
    blockresponse = yield from blockrequest.response
OSError: [Errno -1] No error information

During handling of the above exception, another exception occurred:

Traceback (most recent call last):
  File "/usr/src/homeassistant/homeassistant/core.py", line 1259, in _execute_service
    await handler.func(service_call)
  File "/usr/src/homeassistant/homeassistant/helpers/entity_component.py", line 213, in handle_service
    self._platforms.values(), func, call, service_name, required_features
  File "/usr/src/homeassistant/homeassistant/helpers/service.py", line 349, in entity_service_call
    future.result()  # pop exception if have
  File "/usr/src/homeassistant/homeassistant/helpers/service.py", line 371, in _handle_service_platform_call
    await getattr(entity, func)(**data)
  File "/usr/src/homeassistant/homeassistant/components/tradfri/light.py", line 256, in async_turn_off
    await self._api(self._light_control.set_state(False))
  File "/usr/local/lib/python3.7/site-packages/pytradfri/api/aiocoap_api.py", line 155, in request
    result = await self._execute(api_commands)
  File "/usr/local/lib/python3.7/site-packages/pytradfri/api/aiocoap_api.py", line 146, in _execute
    _, res = await self._get_response(msg)
  File "/usr/local/lib/python3.7/site-packages/pytradfri/api/aiocoap_api.py", line 105, in _get_response
    await self._reset_protocol(e)
  File "/usr/local/lib/python3.7/site-packages/pytradfri/api/aiocoap_api.py", line 78, in _reset_protocol
    await protocol.shutdown()
  File "/usr/local/lib/python3.7/site-packages/aiocoap/protocol.py", line 133, in shutdown
    for exchange_monitor, cancellable in self._active_exchanges.values():
AttributeError: 'NoneType' object has no attribute 'values'
2020-02-22 23:19:26 ERROR (MainThread) [homeassistant.core] Error doing job: Task exception was never retrieved
Traceback (most recent call last):
  File "/usr/local/lib/python3.7/site-packages/pytradfri/api/aiocoap_api.py", line 95, in _get_response
    r = await pr.response
  File "/usr/local/lib/python3.7/site-packages/aiocoap/protocol.py", line 816, in _run_outer
    yield from cls._run(app_request, response, weak_observation, protocol, log, exchange_monitor_factory)
  File "/usr/local/lib/python3.7/site-packages/aiocoap/protocol.py", line 865, in _run
    blockresponse = yield from blockrequest.response
OSError: [Errno -1] No error information

During handling of the above exception, another exception occurred:

Traceback (most recent call last):
  File "/usr/src/homeassistant/homeassistant/core.py", line 1259, in _execute_service
    await handler.func(service_call)
  File "/usr/src/homeassistant/homeassistant/helpers/entity_component.py", line 213, in handle_service
    self._platforms.values(), func, call, service_name, required_features
  File "/usr/src/homeassistant/homeassistant/helpers/service.py", line 349, in entity_service_call
    future.result()  # pop exception if have
  File "/usr/src/homeassistant/homeassistant/helpers/service.py", line 371, in _handle_service_platform_call
    await getattr(entity, func)(**data)
  File "/usr/src/homeassistant/homeassistant/components/tradfri/light.py", line 256, in async_turn_off
    await self._api(self._light_control.set_state(False))
  File "/usr/local/lib/python3.7/site-packages/pytradfri/api/aiocoap_api.py", line 155, in request
    result = await self._execute(api_commands)
  File "/usr/local/lib/python3.7/site-packages/pytradfri/api/aiocoap_api.py", line 146, in _execute
    _, res = await self._get_response(msg)
  File "/usr/local/lib/python3.7/site-packages/pytradfri/api/aiocoap_api.py", line 105, in _get_response
    await self._reset_protocol(e)
  File "/usr/local/lib/python3.7/site-packages/pytradfri/api/aiocoap_api.py", line 78, in _reset_protocol
    await protocol.shutdown()
  File "/usr/local/lib/python3.7/site-packages/aiocoap/protocol.py", line 133, in shutdown
    for exchange_monitor, cancellable in self._active_exchanges.values():
AttributeError: 'NoneType' object has no attribute 'values'
2020-02-22 23:19:26 ERROR (MainThread) [homeassistant.core] Error doing job: Task exception was never retrieved
Traceback (most recent call last):
  File "/usr/local/lib/python3.7/site-packages/pytradfri/api/aiocoap_api.py", line 95, in _get_response
    r = await pr.response
  File "/usr/local/lib/python3.7/site-packages/aiocoap/protocol.py", line 816, in _run_outer
    yield from cls._run(app_request, response, weak_observation, protocol, log, exchange_monitor_factory)
  File "/usr/local/lib/python3.7/site-packages/aiocoap/protocol.py", line 865, in _run
    blockresponse = yield from blockrequest.response
OSError: [Errno -1] No error information

During handling of the above exception, another exception occurred:

Traceback (most recent call last):
  File "/usr/src/homeassistant/homeassistant/core.py", line 1259, in _execute_service
    await handler.func(service_call)
  File "/usr/src/homeassistant/homeassistant/helpers/entity_component.py", line 213, in handle_service
    self._platforms.values(), func, call, service_name, required_features
  File "/usr/src/homeassistant/homeassistant/helpers/service.py", line 349, in entity_service_call
    future.result()  # pop exception if have
  File "/usr/src/homeassistant/homeassistant/helpers/service.py", line 371, in _handle_service_platform_call
    await getattr(entity, func)(**data)
  File "/usr/src/homeassistant/homeassistant/components/tradfri/light.py", line 256, in async_turn_off
    await self._api(self._light_control.set_state(False))
  File "/usr/local/lib/python3.7/site-packages/pytradfri/api/aiocoap_api.py", line 155, in request
    result = await self._execute(api_commands)
  File "/usr/local/lib/python3.7/site-packages/pytradfri/api/aiocoap_api.py", line 146, in _execute
    _, res = await self._get_response(msg)
  File "/usr/local/lib/python3.7/site-packages/pytradfri/api/aiocoap_api.py", line 105, in _get_response
    await self._reset_protocol(e)
  File "/usr/local/lib/python3.7/site-packages/pytradfri/api/aiocoap_api.py", line 78, in _reset_protocol
    await protocol.shutdown()
  File "/usr/local/lib/python3.7/site-packages/aiocoap/protocol.py", line 133, in shutdown
    for exchange_monitor, cancellable in self._active_exchanges.values():
AttributeError: 'NoneType' object has no attribute 'values'
2020-02-22 23:19:26 ERROR (MainThread) [homeassistant.core] Error doing job: Task exception was never retrieved
Traceback (most recent call last):
  File "/usr/local/lib/python3.7/site-packages/pytradfri/api/aiocoap_api.py", line 95, in _get_response
    r = await pr.response
  File "/usr/local/lib/python3.7/site-packages/aiocoap/protocol.py", line 816, in _run_outer
    yield from cls._run(app_request, response, weak_observation, protocol, log, exchange_monitor_factory)
  File "/usr/local/lib/python3.7/site-packages/aiocoap/protocol.py", line 865, in _run
    blockresponse = yield from blockrequest.response
aiocoap.error.RequestTimedOut

During handling of the above exception, another exception occurred:

Traceback (most recent call last):
  File "/usr/src/homeassistant/homeassistant/core.py", line 1259, in _execute_service
    await handler.func(service_call)
  File "/usr/src/homeassistant/homeassistant/helpers/entity_component.py", line 213, in handle_service
    self._platforms.values(), func, call, service_name, required_features
  File "/usr/src/homeassistant/homeassistant/helpers/service.py", line 349, in entity_service_call
    future.result()  # pop exception if have
  File "/usr/src/homeassistant/homeassistant/helpers/service.py", line 371, in _handle_service_platform_call
    await getattr(entity, func)(**data)
  File "/usr/src/homeassistant/homeassistant/components/tradfri/light.py", line 256, in async_turn_off
    await self._api(self._light_control.set_state(False))
  File "/usr/local/lib/python3.7/site-packages/pytradfri/api/aiocoap_api.py", line 155, in request
    result = await self._execute(api_commands)
  File "/usr/local/lib/python3.7/site-packages/pytradfri/api/aiocoap_api.py", line 146, in _execute
    _, res = await self._get_response(msg)
  File "/usr/local/lib/python3.7/site-packages/pytradfri/api/aiocoap_api.py", line 101, in _get_response
    raise RequestTimeout('Request timed out.', e)
pytradfri.error.RequestTimeout: ('Request timed out.', RequestTimedOut())
2020-02-23 01:02:49 WARNING (MainThread) [root] Observation deleted without explicit cancellation
2020-02-23 01:02:49 WARNING (MainThread) [root] Observation deleted without explicit cancellation
2020-02-23 01:02:49 WARNING (MainThread) [root] Observation deleted without explicit cancellation
2020-02-23 01:02:49 WARNING (MainThread) [root] Observation deleted without explicit cancellation
2020-02-23 01:02:49 WARNING (MainThread) [root] Observation deleted without explicit cancellation
2020-02-23 01:02:49 WARNING (MainThread) [root] Observation deleted without explicit cancellation
2020-02-23 01:02:49 WARNING (MainThread) [root] Observation deleted without explicit cancellation
2020-02-23 01:02:49 WARNING (MainThread) [root] Observation deleted without explicit cancellation
2020-02-23 01:02:49 WARNING (MainThread) [root] Observation deleted without explicit cancellation
2020-02-23 01:02:49 WARNING (MainThread) [root] Observation deleted without explicit cancellation
2020-02-23 01:02:49 WARNING (MainThread) [root] Observation deleted without explicit cancellation
2020-02-23 01:02:49 WARNING (MainThread) [root] Observation deleted without explicit cancellation
2020-02-23 01:02:49 WARNING (MainThread) [root] Observation deleted without explicit cancellation
2020-02-23 01:02:49 WARNING (MainThread) [root] Observation deleted without explicit cancellation
2020-02-23 01:02:49 WARNING (MainThread) [root] Observation deleted without explicit cancellation
2020-02-23 01:02:49 WARNING (MainThread) [root] Observation deleted without explicit cancellation
2020-02-23 01:02:49 WARNING (MainThread) [root] Observation deleted without explicit cancellation
2020-02-23 01:02:49 ERROR (MainThread) [homeassistant.core] Error doing job: Task exception was never retrieved
Traceback (most recent call last):
  File "/usr/local/lib/python3.7/site-packages/aiocoap/transports/tinydtls.py", line 160, in _run
    message = yield from self._queue.get()
  File "/usr/local/lib/python3.7/site-packages/aiocoap/util/asyncio.py", line 40, in get
    priority, first = yield from self._inner.get()
  File "/usr/local/lib/python3.7/asyncio/queues.py", line 159, in get
    await getter
concurrent.futures._base.CancelledError

During handling of the above exception, another exception occurred:

Traceback (most recent call last):
  File "/usr/local/lib/python3.7/site-packages/aiocoap/transports/tinydtls.py", line 169, in _run
    self.coaptransport.new_error_callback(-1, self)
  File "/usr/local/lib/python3.7/site-packages/aiocoap/protocol.py", line 195, in _dispatch_error
    self.outgoing_requests.pop(key)
KeyError: (b'\x00\x00p\x15', <aiocoap.transports.tinydtls.DTLSClientConnection object at 0x7311ccd0>)
2020-02-23 17:58:15 WARNING (MainThread) [homeassistant.helpers.entity] Update of media_player.philips_tv is taking over 10 seconds
2020-02-24 15:02:15 ERROR (MainThread) [homeassistant.components.hue.sensor_base] Unable to reach bridge 192.168.1.147 (Error requesting data from 192.168.1.147: None)
2020-02-24 20:14:32 WARNING (MainThread) [homeassistant.helpers.entity] Update of media_player.philips_tv is taking over 10 seconds
2020-02-27 20:42:07 WARNING (MainThread) [homeassistant.helpers.entity] Update of media_player.philips_tv is taking over 10 seconds
2020-02-29 14:25:59 ERROR (MainThread) [homeassistant.components.hue.light] Unable to reach bridge 192.168.1.147 (Error requesting data from 192.168.1.147: None)
2020-03-03 17:28:51 WARNING (MainThread) [homeassistant.helpers.entity] Update of media_player.philips_tv is taking over 10 seconds
